<?xml version="1.0"?>
<robot xmlns:xacro="http://ros.org/wiki/xacro">

<xacro:macro name="servo" params="parent_link *joint_pose">



<link name="servo">
<visual>
<origin xyz="-2.22045e-16 0 -0.0243" rpy="-1.5708 -2.59228e-15 -1.5708" />
<geometry>
<mesh filename="package://grab_it/grab-it-description/meshes/ax_body.stl"/>
</geometry>
<material name="ax_body_material">
<color rgba="0.247059 0.247059 0.247059 1.0"/>
</material>
</visual>
<collision>
<origin xyz="-2.22045e-16 0 -0.0243" rpy="-1.5708 -2.59228e-15 -1.5708" />
<geometry>
<mesh filename="package://grab_it/grab-it-description/meshes/ax_body.stl"/>
</geometry>
<material name="ax_body_material">
<color rgba="0.247059 0.247059 0.247059 1.0"/>
</material>
</collision>
<visual>
<origin xyz="-2.22045e-16 3.46945e-18 -0.00184" rpy="-1.5708 1.64139e-18 -1.31086e-19" />
<geometry>
<mesh filename="package://grab_it/grab-it-description/meshes/ax12_horn.stl"/>
</geometry>
<material name="ax12_horn_material">
<color rgba="0.247059 0.247059 0.247059 1.0"/>
</material>
</visual>
<collision>
<origin xyz="-2.22045e-16 3.46945e-18 -0.00184" rpy="-1.5708 1.64139e-18 -1.31086e-19" />
<geometry>
<mesh filename="package://grab_it/grab-it-description/meshes/ax12_horn.stl"/>
</geometry>
<material name="ax12_horn_material">
<color rgba="0.247059 0.247059 0.247059 1.0"/>
</material>
</collision>
<inertial>
<origin xyz="0.000575587 -0.0548866 0.208652" rpy="0 0 0"/>
<mass value="0.439844" />
<inertia ixx="0.0637573" ixy="-6.08699e-05"  ixz="0.00154971" iyy="0.0679928" iyz="-0.00149064" izz="0.00441436" />
</inertial>
</link>

<joint name="servo_joint" type="continuous">
    <parent link="${parent_link}"/>
<child link="servo" />
    <axis xyz="0 0 1"/>
    <origin xyz="-0.023198 0.00884533 0.983548" rpy="-2.21036 -1.54517 2.19926" />
    <limit effort="30" velocity="10.0"/>
    <dynamics damping="0.0" friction="0.0"/>
  </joint>

  <!-- This block connects the head_swivel joint to an actuator (motor), which informs both
  simulation and visualization of the robot -->
  <transmission name="servo_trans">
    <type>transmission_interface/SimpleTransmission</type>
    <actuator name="servo_motor">
      <mechanicalReduction>1</mechanicalReduction>
    </actuator>
    <joint name="servo_joint">
      <hardwareInterface>hardware_interface/PositionJointInterface</hardwareInterface>
    </joint>
  </transmission>









</xacro:macro>
</robot>
